Workbook

Sheet MASALAH GIZI
A1: Penarikan Data (Update) dilakukan secara rutin 8 jam sekali
A2: Data Tarik : 2026-10-01 04:43:44
A3: No | B3: Kabupaten/Kota | C3: BBLR | E3: Balita | G3: Balita | I3: Balita | K3: Balita Gizi Buruk | M3: Balita Stunting | O3: Insiden Stunting | Q3: Bumil | S3: Bumil Anemia | U3: Rematri Anemia
E4: BB Tidak Naik | G4: BB Kurang | I4: Gizi Kurang | Q4: KEK / Risiko KEK
C6: Jumlah | D6: % | E6: Jumlah | F6: % | G6: Jumlah | H6: % | I6: Jumlah | J6: % | K6: Jumlah | L6: % | M6: Jumlah | N6: % | O6: Jumlah | P6: % | Q6: Jumlah | R6: % | S6: Jumlah | T6: % | U6: Jumlah | V6: %
A7: 1 | B7: CILACAP | C7: 571 | D7: 6.53 | E7: 33778 | F7: 42.845908 | G7: 6263 | H7: 7.93 | I7: 3380 | J7: 4.29 | K7: 515 | L7: 0.51475292 | M7: 4027 | N7: 5.11 | O7: 654 | P7: 0.70005673 | Q7: ='rekap indikator 01102026'!P6 -> 3237 | R7: ='rekap indikator 01102026'!Q6 -> 19.92 | S7: ='rekap indikator 01102026'!L6 -> 856 | T7: ='rekap indikator 01102026'!M6 -> 6.67 | U7: ='rekap indikator 01102026'!H6 -> 4658 | V7: ='rekap indikator 01102026'!I6 -> 16.37
A8: 2 | B8: BANYUMAS | C8: 796 | D8: 9.39 | E8: 33490 | F8: 47.424169 | G8: 8131 | H8: 11.51 | I8: 3383 | J8: 4.79 | K8: 800 | L8: 0.89721303 | M8: 9044 | N8: 12.81 | O8: 937 | P8: 1.2019755 | Q8: ='rekap indikator 01102026'!P7 -> 3115 | R8: ='rekap indikator 01102026'!Q7 -> 19.97 | S8: ='rekap indikator 01102026'!L7 -> 1307 | T8: ='rekap indikator 01102026'!M7 -> 11.55 | U8: ='rekap indikator 01102026'!H7 -> 6631 | V8: ='rekap indikator 01102026'!I7 -> 24.69
A9: 3 | B9: PURBALINGGA | C9: 470 | D9: 9.15 | E9: 19741 | F9: 45.705223 | G9: 4556 | H9: 10.55 | I9: 1805 | J9: 4.18 | K9: 309 | L9: 0.55974205 | M9: 6023 | N9: 13.94 | O9: 822 | P9: 1.7748796 | Q9: ='rekap indikator 01102026'!P8 -> 2467 | R9: ='rekap indikator 01102026'!Q8 -> 23.14 | S9: ='rekap indikator 01102026'!L8 -> 1776 | T9: ='rekap indikator 01102026'!M8 -> 19.47 | U9: ='rekap indikator 01102026'!H8 -> 3684 | V9: ='rekap indikator 01102026'!I8 -> 25.67
A10: 4 | B10: BANJARNEGARA | C10: 319 | D10: 8.07 | E10: 19588 | F10: 46.400569 | G10: 4281 | H10: 10.14 | I10: 1368 | J10: 3.24 | K10: 330 | L10: 0.64037879 | M10: 6785 | N10: 16.07 | O10: 836 | P10: 1.9931812 | Q10: ='rekap indikator 01102026'!P9 -> 2162 | R10: ='rekap indikator 01102026'!Q9 -> 23.35 | S10: ='rekap indikator 01102026'!L9 -> 955 | T10: ='rekap indikator 01102026'!M9 -> 11.89 | U10: ='rekap indikator 01102026'!H9 -> 4372 | V10: ='rekap indikator 01102026'!I9 -> 33.22
A11: 5 | B11: KEBUMEN | C11: 244 | D11: 7.63 | E11: 25304 | F11: 46.934877 | G11: 6098 | H11: 11.31 | I11: 2487 | J11: 4.61 | K11: 72 | L11: 0.10550069 | M11: 4208 | N11: 7.81 | O11: 487 | P11: 0.77253764 | Q11: ='rekap indikator 01102026'!P10 -> 2938 | R11: ='rekap indikator 01102026'!Q10 -> 22.44 | S11: ='rekap indikator 01102026'!L10 -> 2020 | T11: ='rekap indikator 01102026'!M10 -> 26.38 | U11: ='rekap indikator 01102026'!H10 -> 3107 | V11: ='rekap indikator 01102026'!I10 -> 16.06
A12: 6 | B12: PURWOREJO | C12: 103 | D12: 6.41 | E12: 12688 | F12: 46.353938 | G12: 3395 | H12: 12.4 | I12: 1227 | J12: 4.48 | K12: 102 | L12: 0.29430435 | M12: 4518 | N12: 16.51 | O12: 545 | P12: 1.8523554 | Q12: ='rekap indikator 01102026'!P11 -> 1144 | R12: ='rekap indikator 01102026'!Q11 -> 24.02 | S12: ='rekap indikator 01102026'!L11 -> 564 | T12: ='rekap indikator 01102026'!M11 -> 16.33 | U12: ='rekap indikator 01102026'!H11 -> 1586 | V12: ='rekap indikator 01102026'!I11 -> 14.51
A13: 7 | B13: WONOSOBO | C13: 115 | D13: 6.8 | E13: 17124 | F13: 48.281501 | G13: 3357 | H13: 9.47 | I13: 743 | J13: 2.09 | K13: 105 | L13: 0.23151721 | M13: 6356 | N13: 17.92 | O13: 617 | P13: 1.6650924 | Q13: ='rekap indikator 01102026'!P12 -> 819 | R13: ='rekap indikator 01102026'!Q12 -> 22.7 | S13: ='rekap indikator 01102026'!L12 -> 209 | T13: ='rekap indikator 01102026'!M12 -> 10.84 | U13: ='rekap indikator 01102026'!H12 -> 1782 | V13: ='rekap indikator 01102026'!I12 -> 11.56
A14: 8 | B14: MAGELANG | C14: 108 | D14: 7.15 | E14: 23936 | F14: 47.685075 | G14: 5631 | H14: 11.22 | I14: 2330 | J14: 4.64 | K14: 194 | L14: 0.30950368 | M14: 7900 | N14: 15.74 | O14: 1065 | P14: 2.0223311 | Q14: ='rekap indikator 01102026'!P13 -> 1595 | R14: ='rekap indikator 01102026'!Q13 -> 22.93 | S14: ='rekap indikator 01102026'!L13 -> 448 | T14: ='rekap indikator 01102026'!M13 -> 8.89 | U14: ='rekap indikator 01102026'!H13 -> 5830 | V14: ='rekap indikator 01102026'!I13 -> 39.64
A15: 9 | B15: BOYOLALI | C15: 136 | D15: 4.86 | E15: 18116 | F15: 42.246164 | G15: 3769 | H15: 8.79 | I15: 1774 | J15: 4.15 | K15: 39 | L15: 0.072493401 | M15: 5209 | N15: 12.15 | O15: 1132 | P15: 2.3207659 | Q15: ='rekap indikator 01102026'!P14 -> 1669 | R15: ='rekap indikator 01102026'!Q14 -> 19.77 | S15: ='rekap indikator 01102026'!L14 -> 515 | T15: ='rekap indikator 01102026'!M14 -> 10.01 | U15: ='rekap indikator 01102026'!H14 -> 2227 | V15: ='rekap indikator 01102026'!I14 -> 14.01
A16: 10 | B16: KLATEN | C16: 398 | D16: 8.02 | E16: 22164 | F16: 46.814802 | G16: 5834 | H16: 12.32 | I16: 2440 | J16: 5.15 | K16: 421 | L16: 0.71827069 | M16: 6203 | N16: 13.1 | O16: 810 | P16: 1.5953675 | Q16: ='rekap indikator 01102026'!P15 -> 1452 | R16: ='rekap indikator 01102026'!Q15 -> 17.86 | S16: ='rekap indikator 01102026'!L15 -> 581 | T16: ='rekap indikator 01102026'!M15 -> 9.66 | U16: ='rekap indikator 01102026'!H15 -> 4274 | V16: ='rekap indikator 01102026'!I15 -> 21.07
A17: 11 | B17: SUKOHARJO | C17: 267 | D17: 6.04 | E17: 13843 | F17: 38.67516 | G17: 3396 | H17: 9.49 | I17: 1391 | J17: 3.89 | K17: 361 | L17: 0.80513861 | M17: 2792 | N17: 7.8 | O17: 344 | P17: 0.83349486 | Q17: ='rekap indikator 01102026'!P16 -> 686 | R17: ='rekap indikator 01102026'!Q16 -> 16.64 | S17: ='rekap indikator 01102026'!L16 -> 307 | T17: ='rekap indikator 01102026'!M16 -> 11.1 | U17: ='rekap indikator 01102026'!H16 -> 3508 | V17: ='rekap indikator 01102026'!I16 -> 29.37
A18: 12 | B18: WONOGIRI | C18: 146 | D18: 7.9 | E18: 15369 | F18: 48.80597 | G18: 3032 | H18: 9.62 | I18: 1237 | J18: 3.93 | K18: 178 | L18: 0.43998418 | M18: 3051 | N18: 9.69 | O18: 313 | P18: 0.86003187 | Q18: ='rekap indikator 01102026'!P17 -> 1305 | R18: ='rekap indikator 01102026'!Q17 -> 19.83 | S18: ='rekap indikator 01102026'!L17 -> 500 | T18: ='rekap indikator 01102026'!M17 -> 12.67 | U18: ='rekap indikator 01102026'!H17 -> 1241 | V18: ='rekap indikator 01102026'!I17 -> 10.02
... A41: 35 | B41: KOTA TEGAL | C41: 16 | D41: 6.15 | E41: 3570 | F41: 46.624004 | G41: 1188 | H41: 15.51 | I41: 582 | J41: 7.6 | K41: 60 | L41: 0.66115702 | M41: 715 | N41: 9.34 | O41: 51 | P41: 0.56818182 | Q41: ='rekap indikator 01102026'!P40 -> 480 | R41: ='rekap indikator 01102026'!Q40 -> 21.82 | S41: ='rekap indikator 01102026'!L40 -> 352 | T41: ='rekap indikator 01102026'!M40 -> 21.99 | U41: ='rekap indikator 01102026'!H40 -> 1401 | V41: ='rekap indikator 01102026'!I40 -> 26.07
B42: JAWA TENGAH | C42: 7374 | D42: 6.24 | E42: 626629 | F42: 42.859468 | G42: 140875 | H42: 9.63 | I42: 67989 | J42: 4.65 | K42: 12077 | L42: 0.6592015 | M42: 141184 | N42: 9.66 | O42: 21403 | P42: 1.288873 | Q42: ='rekap indikator 01102026'!P41 -> 55144 | R42: ='rekap indikator 01102026'!Q41 -> 19.94 | S42: ='rekap indikator 01102026'!L41 -> 22512 | T42: ='rekap indikator 01102026'!M41 -> 11.16 | U42: ='rekap indikator 01102026'!H41 -> 88202 | V42: ='rekap indikator 01102026'!I41 -> 15.21
A43: TARGET | C43: ≤5,5% | E43: ≤40% | G43: ≤14% | I43: Wasting ≤7,5 % | K43: ≤0,5 % | M43: ≤14 % | O43: 2.3 | Q43: ≤13% | S43: ≤23% | U43: ≤25%

Sheet rekap indikator 01102026
A1: Penarikan Data (Update) dilakukan secara rutin 8 jam sekali
A2: Data Tarik : 2026-10-01 04:43:44
A3: No | B3: Kabupaten/Kota
A4: No | B4: Kabupaten/Kota | C4: Prev Stunting SSGI 2024 | D4: Rematri Konsumsi TTD | E4: % Konsumsi TTD | F4: Rematri skrining anemia | G4: % skrining anemia | H4: Rematri anemia | I4: % Rematri anemia | J4: ibu hamil ANC 6x | K4: % ANC 6x | L4: ibu hamil Anemia | M4: % bumil Anemia | N4: Ibu hamil Konsumsi TTD/MMS | O4: % TTD/MMS | P4: ibu hamil KEK | Q4: % Bumil KEK | R4: Jumlah ibu hamil KEK Konsumsi MT | S4: % Bumil PMT | T4: Balita dipantau pertumbuhan (D/S) | U4: % D/S | V4: Jumlah balita dipantau tumbang | W4: % tumbang | X4: Jumlah balita dipantau tumbang (manual) | Y4: % | Z4: ASI Eksklusif | AA4: % ASI | AB4: MPASI | AC4: % MPASI | AD4: Jumlah gizi kurang | AE4: Jumlah gizi kurang dapat MT | AF4: % gizi kurang dapat MT | AG4: Jumlah BB kurang | AH4: Jumlah BB kurang dapat MT | AI4: % BB kurang dapat MT | AJ4: Jumlah BB Tidak Naik (T) | AK4: Jumlah BB Tidak Naik (T) dapat MT | AL4: % BB Tidak Naik (T) dapat MT | AM4: Jumlah kasus gizi buruk | AN4: Jumlah Kasus Gizi Buruk mendapat tatalaksana | AO4: % talak gibur | AP4: Sasaran IDL | AQ4: Baduta IDL | AR4: % IDL | AS4: Total Capaian Intervensi
E5: 1 | G5: 2 | K5: 3 | O5: 4 | S5: 5 | U5: 6 | W5: 7 | AA5: 8 | AC5: 9 | AF5: 10 | AI5: 11 | AL5: 12 | AO5: 13 | AR5: 14
A6: 1 | B6: CILACAP | C6: 15,6 | D6: 77877 | E6: 98.78 | F6: 28458 | G6: 94.87 | H6: 4658 | I6: 16.37 | J6: 5342 | K6: 64.43 | L6: 856 | M6: 6.67 | N6: 4827 | O6: 14.05 | P6: 3237 | Q6: 19.92 | R6: 212 | S6: 25.45 | T6: 78836 | U6: 97.77 | V6: 53324 | W6: 56.24 | Z6: 8479 | AA6: 90.43 | AB6: 8317 | AC6: 95.78 | AD6: 15736 | AE6: 1508 | AF6: 9.58 | AG6: 19079 | AH6: 1419 | AI6: 7.44 | AJ6: 115951 | AK6: 2051 | AL6: 1.77 | AM6: 376 | AN6: 96 | AO6: 25.53 | AP6: 31615 | AQ6: 12411 | AR6: 39.256682 | AS6: 7
A7: 2 | B7: BANYUMAS | C7: 19,6 | D7: 80194 | E7: 100 | F7: 26853 | G7: 100 | H7: 6631 | I7: 24.69 | J7: 3711 | K7: 48.38 | L7: 1307 | M7: 11.55 | N7: 3942 | O7: 15.16 | P7: 3115 | Q7: 19.97 | R7: 174 | S7: 16.91 | T7: 70618 | U7: 99.51 | V7: 27468 | W7: 11.35 | Z7: 10536 | AA7: 88.12 | AB7: 8700 | AC7: 97.8 | AD7: 24614 | AE7: 1781 | AF7: 7.24 | AG7: 42169 | AH7: 1314 | AI7: 3.12 | AJ7: 193142 | AK7: 4675 | AL7: 2.42 | AM7: 799 | AN7: 510 | AO7: 63.83 | AP7: 23858 | AQ7: 10140 | AR7: 42.501467 | AS7: 6
A8: 3 | B8: PURBALINGGA | C8: 22,3 | D8: 42770 | E8: 99.94 | F8: 14352 | G8: 99.14 | H8: 3684 | I8: 25.67 | J8: 3028 | K8: 53.15 | L8: 1776 | M8: 19.47 | N8: 2120 | O8: 11.92 | P8: 2467 | Q8: 23.14 | R8: 346 | S8: 47.59 | T8: 43192 | U8: 96.49 | V8: 15668 | W8: 23.86 | Z8: 6805 | AA8: 88.99 | AB8: 4243 | AC8: 88.8 | AD8: 8472 | AE8: 856 | AF8: 10.1 | AG8: 17242 | AH8: 1101 | AI8: 6.39 | AJ8: 77197 | AK8: 2733 | AL8: 3.54 | AM8: 283 | AN8: 70 | AO8: 24.73 | AP8: 16754 | AQ8: 6699 | AR8: 39.984481 | AS8: 6
A9: 4 | B9: BANJARNEGARA | C9: 20,6 | D9: 39209 | E9: 96.43 | F9: 13161 | G9: 93.03 | H9: 4372 | I9: 33.22 | J9: 2885 | K9: 59.61 | L9: 955 | M9: 11.89 | N9: 2997 | O9: 19.4 | P9: 2162 | Q9: 23.35 | R9: 381 | S9: 32.21 | T9: 42215 | U9: 94.76 | V9: 13057 | W9: 8.93 | Z9: 5652 | AA9: 88.05 | AB9: 5066 | AC9: 91.99 | AD9: 8372 | AE9: 865 | AF9: 10.33 | AG9: 22333 | AH9: 1334 | AI9: 5.97 | AJ9: 99819 | AK9: 4622 | AL9: 4.63 | AM9: 313 | AN9: 131 | AO9: 41.85 | AP9: 14328 | AQ9: 6516 | AR9: 45.477387 | AS9: 6
A10: 5 | B10: KEBUMEN | C10: 18,0 | D10: 52447 | E10: 92.32 | F10: 19351 | G10: 90.37 | H10: 3107 | I10: 16.06 | J10: 490 | K10: 8.74 | L10: 2020 | M10: 26.38 | N10: 1393 | O10: 6.43 | P10: 2938 | Q10: 22.44 | R10: 125 | S10: 16.76 | T10: 53913 | U10: 98.24 | V10: 2533 | W10: 2.35 | Z10: 7923 | AA10: 91.65 | AB10: 5672 | AC10: 93.47 | AD10: 10801 | AE10: 580 | AF10: 5.37 | AG10: 16691 | AH10: 1160 | AI10: 6.95 | AJ10: 75553 | AK10: 3968 | AL10: 5.25 | AM10: 53 | AN10: 10 | AO10: 18.87 | AP10: 19762 | AQ10: 6908 | AR10: 34.955976 | AS10: 5
A11: 6 | B11: PURWOREJO | C11: 14,9 | D11: 29322 | E11: 87.26 | F11: 10932 | G11: 98.68 | H11: 1586 | I11: 14.51 | J11: 615 | K11: 24.86 | L11: 564 | M11: 16.33 | N11: 754 | O11: 5.95 | P11: 1144 | Q11: 24.02 | R11: 112 | S11: 18.82 | T11: 27372 | U11: 98.31 | V11: 3467 | W11: 10.15 | Z11: 3292 | AA11: 92.89 | AB11: 3226 | AC11: 97.4 | AD11: 3573 | AE11: 264 | AF11: 7.39 | AG11: 7482 | AH11: 704 | AI11: 9.41 | AJ11: 27069 | AK11: 960 | AL11: 3.55 | AM11: 81 | AN11: 20 | AO11: 24.69 | AP11: 11687 | AQ11: 4265 | AR11: 36.49354 | AS11: 5
A12: 7 | B12: WONOSOBO | C12: 23,9 | D12: 36372 | E12: 99.73 | F12: 15415 | G12: 97.15 | H12: 1782 | I12: 11.56 | J12: 190 | K12: 14.81 | L12: 209 | M12: 10.84 | N12: 269 | O12: 1.96 | P12: 819 | Q12: 22.7 | R12: 190 | S12: 19.37 | T12: 35467 | U12: 97 | V12: 656 | W12: 1.77 | Z12: 3909 | AA12: 92.13 | AB12: 3411 | AC12: 98.81 | AD12: 3997 | AE12: 243 | AF12: 6.08 | AG12: 14071 | AH12: 742 | AI12: 5.27 | AJ12: 66879 | AK12: 1504 | AL12: 2.25 | AM12: 87 | AN12: 18 | AO12: 20.69 | AP12: 12548 | AQ12: 5089 | AR12: 40.556264 | AS12: 5
A13: 8 | B13: MAGELANG | C13: 19,3 | D13: 43774 | E13: 87.23 | F13: 14706 | G13: 86.58 | H13: 5830 | I13: 39.64 | J13: 748 | K13: 26.97 | L13: 448 | M13: 8.89 | N13: 1114 | O13: 5.07 | P13: 1595 | Q13: 22.93 | R13: 242 | S13: 25.99 | T13: 50196 | U13: 95.68 | V13: 2990 | W13: 3.42 | Z13: 4779 | AA13: 96.72 | AB13: 3689 | AC13: 94.23 | AD13: 9366 | AE13: 286 | AF13: 3.05 | AG13: 17379 | AH13: 637 | AI13: 3.67 | AJ13: 78815 | AK13: 1073 | AL13: 1.36 | AM13: 167 | AN13: 3 | AO13: 1.8 | AP13: 20070 | AQ13: 8932 | AR13: 44.504235 | AS13: 5
A14: 9 | B14: BOYOLALI | C14: 24,5 | D14: 44948 | E14: 99.38 | F14: 15901 | G14: 100.77 | H14: 2227 | I14: 14.01 | J14: 873 | K14: 22.35 | L14: 515 | M14: 10.01 | N14: 1082 | O14: 7.12 | P14: 1669 | Q14: 19.77 | R14: 86 | S14: 22.63 | T14: 42882 | U14: 96.98 | V14: 3517 | W14: 2.83 | Z14: 5426 | AA14: 90.13 | AB14: 3162 | AC14: 95.5 | AD14: 4319 | AE14: 593 | AF14: 13.73 | AG14: 6305 | AH14: 622 | AI14: 9.87 | AJ14: 31106 | AK14: 3144 | AL14: 10.11 | AM14: 37 | AN14: 11 | AO14: 29.73 | AP14: 14055 | AQ14: 5876 | AR14: 41.807186 | AS14: 4
A15: 10 | B15: KLATEN | C15: 20,8 | D15: 43248 | E15: 92.23 | F15: 20288 | G15: 98.87 | H15: 4274 | I15: 21.07 | J15: 1614 | K15: 37.94 | L15: 581 | M15: 9.66 | N15: 2065 | O15: 10.96 | P15: 1452 | Q15: 17.86 | R15: 285 | S15: 35.36 | T15: 47344 | U15: 98.59 | V15: 10341 | W15: 8.47 | Z15: 8088 | AA15: 93.51 | AB15: 5143 | AC15: 89.06 | AD15: 15100 | AE15: 1386 | AF15: 9.18 | AG15: 25656 | AH15: 1241 | AI15: 4.84 | AJ15: 104337 | AK15: 1271 | AL15: 1.22 | AM15: 381 | AN15: 121 | AO15: 31.76 | AP15: 17328 | AQ15: 7033 | AR15: 40.587488 | AS15: 5
A16: 11 | B16: SUKOHARJO | C16: 16,8 | D16: 37428 | E16: 99.47 | F16: 11943 | G16: 95.52 | H16: 3508 | I16: 29.37 | J16: 169 | K16: 7.91 | L16: 307 | M16: 11.1 | N16: 1770 | O16: 12.45 | P16: 686 | Q16: 16.64 | R16: 565 | S16: 47.32 | T16: 35793 | U16: 99.91 | V16: 16471 | W16: 17.08 | Z16: 5886 | AA16: 91.38 | AB16: 4506 | AC16: 99.51 | AD16: 10670 | AE16: 1557 | AF16: 14.59 | AG16: 18394 | AH16: 1084 | AI16: 5.89 | AJ16: 79616 | AK16: 7351 | AL16: 9.23 | AM16: 394 | AN16: 283 | AO16: 71.83 | AP16: 13304 | AQ16: 6763 | AR16: 50.834336 | AS16: 5
A17: 12 | B17: WONOGIRI | C17: 15,1 | D17: 36250 | E17: 99.96 | F17: 12389 | G17: 94.53 | H17: 1241 | I17: 10.02 | J17: 299 | K17: 8.36 | L17: 500 | M17: 12.67 | N17: 588 | O17: 4.74 | P17: 1305 | Q17: 19.83 | R17: 157 | S17: 28.86 | T17: 31490 | U17: 99.45 | V17: 5168 | W17: 8.68 | Z17: 2636 | AA17: 78.78 | AB17: 1519 | AC17: 94.58 | AD17: 4384 | AE17: 303 | AF17: 6.91 | AG17: 8389 | AH17: 354 | AI17: 4.22 | AJ17: 47613 | AK17: 2876 | AL17: 6.04 | AM17: 151 | AN17: 59 | AO17: 39.07 | AP17: 11540 | AQ17: 4629 | AR17: 40.112652 | AS17: 5
... A40: 35 | B40: KOTA TEGAL | C40: 18,0 | D40: 12156 | E40: 97.96 | F40: 5375 | G40: 98.39 | H40: 1401 | I40: 26.07 | J40: 101 | K40: 10.07 | L40: 352 | M40: 21.99 | N40: 176 | O40: 3.55 | P40: 480 | Q40: 21.82 | R40: 33 | S40: 9.22 | T40: 7657 | U40: 98.41 | V40: 277 | W40: 4.71 | Z40: 812 | AA40: 92.17 | AB40: 845 | AC40: 96.68 | AD40: 1648 | AE40: 4 | AF40: 0.24 | AG40: 2084 | AH40: 30 | AI40: 1.44 | AJ40: 7328 | AK40: 211 | AL40: 2.88 | AM40: 40 | AN40: 2 | AO40: 5 | AP40: 4618 | AQ40: 3054 | AR40: 66.132525 | AS40: 5
B41: JAWA TENGAH | C41: 17,1 | D41: 1483925 | E41: 93.64 | F41: 579995 | G41: 93.76 | H41: 88202 | I41: 15.21 | J41: 49129 | K41: 39.64 | L41: 22512 | M41: 11.16 | N41: 64599 | O41: 10.9 | P41: 55144 | Q41: 19.94 | R41: 7750 | S41: 26.44 | T41: 1462055 | U41: 96.13 | V41: 312523 | W41: 11.73 | Z41: 179652 | AA41: 89.77 | AB41: 141953 | AC41: 95.31 | AD41: 334648 | AE41: 27677 | AF41: 8.27 | AG41: 485088 | AH41: 30651 | AI41: 6.32 | AJ41: 2381579 | AK41: 80218 | AL41: 3.37 | AM41: 10481 | AN41: 4036 | AO41: 38.51 | AP41: 547843 | AQ41: 250212 | AR41: 45.672209 | AS41: 5
B42: TARGET | D42: 67 | F42: 77 | H42: ≤23 | J42: tw3: 60 | L42: ≤25 | N42: tw 3: 39 | P42: ≤13 | R42: 85 | T42: 90 | V42: 55 | X42: 55 | Z42: 76 | AB42: 76 | AE42: 70 | AH42: 70 | AK42: 70 | AN42: 92 | AQ42: TW3: 56,25

Sheet capaian intervensi spesifik
C4: No | F4: Intervensi Percepatan Penurunan Stunting | G4: Target 2025 | H4: Capaian 2025 | I4: Target 2026 | J4: Jumlah | K4: Capaian TW 1 | L4: Jumlah | M4: Capaian TW 2 | N4: Capaian TW 2 | O4: Capaian TW 3 | P4: Capaian TW 4 | Q4: Status
B5: Intervensi untuk remaja putri dan ibu hamil (sebelum kelahiran) | C5: 1 | F5: Remaja putri mendapat skrining anemia | G5: 0.75 | H5: 90.58 | I5: 0.77 | J5: 441539 | K5: 84.094017 | L5: ='rekap indikator 01102026'!F41 -> 579995 | M5: ='rekap indikator 01102026'!G41 -> 93.76 | Q5: On track
C6: 2 | F6: Remaja putri mengonsumsi TTD (tablet tambah darah) | G6: 0.65 | H6: 89.34 | I6: 0.67 | J6: 1213204 | K6: 76.057797 | L6: ='rekap indikator 01102026'!D41 -> 1483925 | M6: ='rekap indikator 01102026'!E41 -> 93.64 | Q6: On track
C7: 3 | F7: Ibu hamil ANC minimal 6x* | G7: 0.8 | H7: 91.46 | I7: 0.2 | J7: 109144 | K7: 28 | L7: ='rekap indikator 01102026'!J41 -> 49129 | M7: ='rekap indikator 01102026'!K41 -> 39.64 | Q7: On track
C8: 4 | F8: Ibu hamil mengonsumsi suplementasi gizi (TTD/MMS) minimal 180 tablet selama kehamilan** | G8: 0.48 | H8: 91.1 | I8: 0.13 | J8: 43365 | K8: 7.274481 | L8: ='rekap indikator 01102026'!N41 -> 64599 | M8: ='rekap indikator 01102026'!O41 -> 10.9 | Q8: Perlu percepatan
C9: 5 | F9: Ibu hamil KEK mendapat tambahan asupan gizi | G9: 0.84 | H9: 71.72 | I9: 0.85 | J9: 136 | K9: 0.49544627 | L9: ='rekap indikator 01102026'!R41 -> 7750 | M9: ='rekap indikator 01102026'!S41 -> 26.44 | Q9: Perlu percepatan
B10: Intervensi untuk balita (setelah kelahiran) | C10: 6a | F10: Pemantauan pertumbuhan balita | G10: 0.8 | H10: 94.38 | I10: 0.85 | J10: 1695390 | K10: 96.083201 | L10: ='rekap indikator 01102026'!T41 -> 1462055 | M10: ='rekap indikator 01102026'!U41 -> 96.13 | Q10: On track
C11: 6b | F11: Pemantauan pertumbuhan dan perkembangan balita | G11: 0.5 | H11: 88.51 | I11: 0.55 | J11: 258722 | K11: 8.8285958 | L11: ='rekap indikator 01102026'!V41 -> 312523 | M11: ='rekap indikator 01102026'!W41 -> 11.73 | Q11: Perlu percepatan
C12: 7 | F12: Bayi usia kurang dari 6 bulan mendapat ASI eksklusif | G12: 0.73 | H12: 90.24 | I12: 0.76 | J12: 75827 | K12: 88.46616 | L12: ='rekap indikator 01102026'!Z41 -> 179652 | M12: ='rekap indikator 01102026'!AA41 -> 89.77 | Q12: On track
C13: 8 | F13: Anak 6-23 bulan mendapat MP-ASI | G13: 0.73 | H13: 93.66 | I13: 0.76 | J13: 382643 | K13: 95.526328 | L13: ='rekap indikator 01102026'!AB41 -> 141953 | M13: ='rekap indikator 01102026'!AC41 -> 95.31 | Q13: On track
C14: 9a | F14: Balita berat badan tidak naik (T) mendapat tambahan asupan gizi | G14: 0.65 | H14: 23.4 | I14: 0.7 | J14: 4082 | K14: 0.54443 | L14: ='rekap indikator 01102026'!AK41 -> 80218 | M14: ='rekap indikator 01102026'!AL41 -> 3.37 | Q14: Perlu percepatan
C15: 9b | F15: Balita berat badan kurang mendapat tambahan asupan gizi | G15: 0.65 | H15: 55.6 | I15: 0.7 | J15: 638 | K15: 0.44116223 | L15: ='rekap indikator 01102026'!AH41 -> 30651 | M15: ='rekap indikator 01102026'!AI41 -> 6.32 | Q15: Perlu percepatan
C16: 9c | F16: Balita gizi kurang mendapat tambahan asupan gizi | G16: 0.65 | H16: 59.81 | I16: 0.7 | J16: 571 | K16: 0.5438665 | L16: ='rekap indikator 01102026'!AE41 -> 27677 | M16: ='rekap indikator 01102026'!AF41 -> 8.27 | Q16: Perlu percepatan
C17: 9d | F17: Balita gizi buruk mendapat pelayanan tata laksana gizi buruk | G17: 0.91 | H17: 96.86 | I17: 0.92 | J17: 303 | K17: 21.814255 | L17: ='rekap indikator 01102026'!AN41 -> 4036 | M17: ='rekap indikator 01102026'!AO41 -> 38.51 | Q17: Perlu percepatan
C18: 10 | F18: Baduta memperoleh imunisasi lengkap | G18: 0.97 | H18: 99.46 | I18: 0.97 | J18: 65845 | K18: 12.018954 | L18: ='rekap indikator 01102026'!AQ41 -> 250212 | M18: ='rekap indikator 01102026'!AR41 -> 45.672209 | Q18: Perlu percepatan
B19: Intervensi lintas siklus hidup | C19: 11 | F19: Kab/Kota yang telah terverifikasi 100% Kepala Keluarga stop Buang Air Besar Sembarangan (BABS)*** | G19: 8653 desa | H19: 100 | I19: 8653 desa | J19: 8653 desa | K19: 100 | L19: 8653 desa | M19: 100 | Q19: On track

Sheet idl
C2: IDL | F2: IBL
A3: Provinsi (ID) | B3: Kab/Kota (ID) | C3: Sasaran | D3: Cakupan | E3: (%) Capaian | F3: Sasaran | G3: Cakupan | H3: (%) Capaian
A4: 33 - JAWA TENGAH | B4: 3301 - KAB. CILACAP | C4: 31615 | D4: 12411 | E4: =D4/C4*100 -> 39.256682 | F4: 31592 | G4: 13770 | H4: 0.43586984
B5: 3302 - KAB. BANYUMAS | C5: 23858 | D5: 10140 | E5: =D5/C5*100 -> 42.501467 | F5: 23883 | G5: 9925 | H5: 0.41556756
B6: 3303 - KAB. PURBALINGGA | C6: 16754 | D6: 6699 | E6: =D6/C6*100 -> 39.984481 | F6: 16571 | G6: 6917 | H6: 0.41741597
B7: 3304 - KAB. BANJARNEGARA | C7: 14328 | D7: 6516 | E7: =D7/C7*100 -> 45.477387 | F7: 14295 | G7: 6982 | H7: 0.48842253
B8: 3305 - KAB. KEBUMEN | C8: 19762 | D8: 6908 | E8: =D8/C8*100 -> 34.955976 | F8: 19738 | G8: 6821 | H8: 0.34557706
B9: 3306 - KAB. PURWOREJO | C9: 11687 | D9: 4265 | E9: =D9/C9*100 -> 36.49354 | F9: 11678 | G9: 4371 | H9: 0.37429354
B10: 3307 - KAB. WONOSOBO | C10: 12548 | D10: 5089 | E10: =D10/C10*100 -> 40.556264 | F10: 12545 | G10: 5330 | H10: 0.42487047
B11: 3308 - KAB. MAGELANG | C11: 20070 | D11: 8932 | E11: =D11/C11*100 -> 44.504235 | F11: 20052 | G11: 9128 | H11: 0.45521644
B12: 3309 - KAB. BOYOLALI | C12: 14055 | D12: 5876 | E12: =D12/C12*100 -> 41.807186 | F12: 14042 | G12: 5597 | H12: 0.39858994
B13: 3310 - KAB. KLATEN | C13: 17328 | D13: 7033 | E13: =D13/C13*100 -> 40.587488 | F13: 17287 | G13: 6763 | H13: 0.39121883
B14: 3311 - KAB. SUKOHARJO | C14: 13304 | D14: 6763 | E14: =D14/C14*100 -> 50.834336 | F14: 13280 | G14: 6531 | H14: 0.49179217
B15: 3312 - KAB. WONOGIRI | C15: 11540 | D15: 4629 | E15: =D15/C15*100 -> 40.112652 | F15: 11642 | G15: 4647 | H15: 0.39915822
B16: 3313 - KAB. KARANGANYAR | C16: 12969 | D16: 5738 | E16: =D16/C16*100 -> 44.243966 | F16: 12991 | G16: 5681 | H16: 0.43730275
... B38: 3376 - KOTA TEGAL | C38: 4618 | D38: 3054 | E38: =D38/C38*100 -> 66.132525 | F38: 4590 | G38: 2647 | H38: 0.57668845
C39: =SUM(C4:C38) -> 547843 | D39: =SUM(D4:D38) -> 250212 | E39: =D39/C39*100 -> 45.672209 | F39: =SUM(F4:F38) -> 546781 | G39: =SUM(G4:G38) -> 250520 | H39: =G39/F39*100 -> 45.817247

Sheet anak
A1: Data Tarik : 2026-10-01 04:32:23
A2: Penarikan Data (Update) dilakukan secara rutin 8 jam sekali
A3: No | B3: Kabupaten/Kota | C3: Jumlah bayi baru lahir hidup | D3: Bayi baru lahir | S3: Pemantauan Pertumbuhan | AE3: Pemantauan Pertumbuhan dan Perkembangan | AN3: Cakupan balita dan anak prasekolah dilayani SDIDTK/PPP di FKTP | AR3: Persentase balita dan anak prasekolah yang terdeteksi ada gangguan atau penyimpangan perkembangan | BD3: Persentase Balita dan Anak Prasekolah dengan kelengkapan pengisian Buku KIA bagian pemantauan perkembangan | BF3: Persentase Balita dan Anak Prasekolah yang mengikut Kelas Ibu Balita minimal 4 kali | BJ3: Cakupan bayi dilayani PKAT (Pemeriksaan Kesehatan Anak Terintegrasi)
D4: Persentase bayi lahir prematur | F4: Persentase bayi dengan berat badan lahir rendah (berat badan < 2500 gram) | H4: Persentase panjang bayi lahir rendah | J4: Persentase lingkar kepala bayi lahir rendah | L4: Persentase bayi prematur dan BBLR yang mendapat buku KIA bayi kecil | O4: Persentase bayi baru lahir dengan BBLR mendapat tata laksana | Q4: Persentase bayi yang baru lahir mendapat IMD | S4: Jumlah sasaran balita | T4: Jumlah sasaran balita bulan ini | U4: Jumlah balita ditimbang bulan ini | V4: % | W4: Jumlah balita punya buku KIA bulan ini | X4: % | Y4: Jumlah sasaran anak prasekolah (60-83 bulan) | Z4: Jumlah anak prasekolah (60-83 bulan) bulan ini | AA4: Jumlah anak prasekolah (60-83 bulan) ditimbang bulan ini | AB4: % | AC4: Jumlah anak prasekolah (60-83 bulan) punya buku KIA bulan ini | AD4: % | AE4: Jumlah balita usia 12-23 bulan sampai TW ini | AF4: Jumlah balita usia 12-23 bulan (yang berulang tahun di bulan ini) dipantau pertumbuhan dan perkembangan | AG4: % | AH4: Jumlah balita usia 24-59 bulan sampai TW ini | AI4: Jumlah balita usia 24-59 bulan (yang berulang tahun di bulan ini) dipantau pertumbuhan dan perkembangan | AJ4: % | AK4: Jumlah balita usia 12-59 bulan sampai TW ini | AL4: Jumlah balita usia 12-59 bulan yang dipantau pertumbuhan dan perkembangan TW ini | AM4: % | AN4: Jumlah balita mendapat pelayanan SDIDTK/PPP di Fasyankes bulan ini | AO4: % | AP4: Jumlah anak prasekolah mendapat pelayanan SDIDTK/PPP di Fasyankes bulan ini | AQ4: % | AR4: Jumlah balita dengan hasil perkembangan sesuai bulan ini | AS4: Jumlah balita dengan hasil perkembangan meragukan bulan ini | AT4: Jumlah balita dengan hasil perkembangan kemungkinan penyimpangan bulan ini | AU4: Jumlah balita dengan hasil perkembangan meragukan yang mendapat intervensi bulan ini | AV4: Jumlah balita dengan hasil perkembangan kemungkinan penyimpangan yang mendapat intervensi bulan ini | AW4: % | AX4: Jumlah anak prasekolah dengan hasil perkembangan sesuai bulan ini | AY4: Jumlah anak prasekolah dengan hasil perkembangan meragukan bulan ini | AZ4: Jumlah anak prasekolah dengan hasil perkembangan kemungkinan penyimpangan bulan ini | BA4: Jumlah anak prasekolah dengan hasil perkembangan meragukan yang mendapat intervensi bulan ini | BB4: Jumlah anak prasekolah dengan hasil perkembangan kemungkinan penyimpangan yang mendapat intervensi bulan ini | BC4: % | BD4: Jumlah balita yang Buku KIA nya terisi lengkap bagian pemantauan perkembangan | BE4: Jumlah anak prasekolah yang Buku KIA nya terisi lengkap bagian pemantauan perkembangan | BF4: Jumlah balita yang ibu/orangtua/wali/keluarga/pengasuh telah mengikuti minimal 4 (empat) kali kelas ibu balita | BG4: % | BH4: Jumlah anak prasekolah yang ibu/orangtua/wali/keluarga/pengasuh telah mengikuti minimal 4 (empat) kali kelas ibu balita | BI4: % | BJ4: Cakupan bayi dilayani PKAT (Pemeriksaan Kesehatan Anak Terintegrasi)
D5: Jumlah bayi lahir < 37 minggu | E5: % | F5: Jumlah bayi BBLR | G5: % | H5: Jumlah Bayi PBLR | I5: % | J5: Jumlah lingkar kepala bayi lahir rendah | K5: % | L5: Jumlah bayi yang prematur dan BBLR | M5: Jumlah bayi prematur dan BBLR yang mendapat buku KIA bayi kecil | N5: % | O5: Jumlah bayi baru lahir dengan BBLR mendapat tata laksana | P5: % | Q5: Jumlah Bayi Mendapat IMD | R5: % | BJ5: Jumlah bayi usia 6 bulan - 6 bulan 29 hari | BK5: Jumlah bayi usia 6 bulan - 6 bulan 29 hari yang dilayani PKAT | BL5: %
A6: [1] | B6: [2] | C6: [3] | D6: [4] | E6: [5] | F6: [6] | G6: [7] | H6: [8] | I6: [9] | J6: [10] | K6: [11] | L6: [12] | M6: [13] | N6: [14] | O6: [15] | P6: [16] | Q6: [17] | R6: [18] | S6: [19] | T6: [20] | U6: [21] | V6: [22] | W6: [23] | X6: [24] | Y6: [25] | Z6: [26] | AA6: [27] | AB6: [28] | AC6: [29] | AD6: [30] | AE6: [31] | AF6: [32] | AG6: [33] | AH6: [34] | AI6: [35] | AJ6: [36] | AK6: [37] | AL6: [38] | AM6: [39] | AN6: [40] | AO6: [41] | AP6: [42] | AQ6: [43] | AR6: [44] | AS6: [45] | AT6: [46] | AU6: [47] | AV6: [48] | AW6: [49] | AX6: [50] | AY6: [51] | AZ6: [52] | BA6: [53] | BB6: [54] | BC6: [55] | BD6: [56] | BE6: [57] | BF6: [58] | BG6: [59] | BH6: [60] | BI6: [61] | BJ6: [62] | BK6: [63] | BL6: [64]
A7: 1 | B7: KABUPATEN CILACAP | C7: 8738 | D7: 945 | E7: 10.81 | F7: 571 | G7: 6.53 | H7: 1752 | I7: 20.05 | J7: 1428 | K7: 16.34 | L7: 1185 | M7: 210 | N7: 17.72 | O7: 218 | P7: 38.18 | Q7: 8380 | R7: 95.9 | S7: 157153 | T7: 80534 | U7: 78886 | V7: 97.95 | W7: 79392 | X7: 98.58 | Y7: 56930 | Z7: 35260 | AA7: 1693 | AB7: 4.8 | AC7: 34110 | AD7: 96.74 | AE7: 17994 | AF7: 10025 | AG7: 55.71 | AH7: 76813 | AI7: 43299 | AJ7: 56.37 | AK7: 94807 | AL7: 53324 | AM7: 56.24 | AN7: 48037 | AO7: 30.57 | AP7: 29133 | AQ7: 51.17 | AR7: 69941 | AS7: 1368 | AT7: 550 | AU7: 566 | AV7: 77 | AW7: 33.52 | AX7: 30917 | AY7: 444 | AZ7: 180 | BA7: 95 | BB7: 169 | BC7: 42.31 | BD7: 10658 | BE7: 4066 | BF7: 3068 | BG7: 3.81 | BH7: 110 | BI7: 0.31 | BJ7: 20648 | BK7: 5464 | BL7: 26.46
A8: 2 | B8: KABUPATEN BANYUMAS | C8: 8481 | D8: 778 | E8: 9.17 | F8: 796 | G8: 9.39 | H8: 2210 | I8: 26.06 | J8: 973 | K8: 11.47 | L8: 1069 | M8: 637 | N8: 59.59 | O8: 578 | P8: 72.61 | Q8: 7864 | R8: 92.72 | S8: 118980 | T8: 70835 | U8: 70548 | V8: 99.59 | W8: 70504 | X8: 99.53 | Y8: 54547 | Z8: 31462 | AA8: 2892 | AB8: 9.19 | AC8: 31335 | AD8: 99.6 | AE8: 50706 | AF8: 6113 | AG8: 12.06 | AH8: 191342 | AI8: 21355 | AJ8: 11.16 | AK8: 242048 | AL8: 27468 | AM8: 11.35 | AN8: 64787 | AO8: 54.45 | AP8: 23949 | AQ8: 43.91 | AR8: 77573 | AS8: 1573 | AT8: 106 | AU8: 101 | AV8: 141 | AW8: 14.41 | AX8: 27016 | AY8: 476 | AZ8: 44 | BA8: 11 | BB8: 45 | BC8: 10.77 | BD8: 18023 | BE8: 7310 | BF8: 2653 | BG8: 3.75 | BH8: 167 | BI8: 0.53 | BJ8: 17539 | BK8: 8010 | BL8: 45.67
A9: 3 | B9: KABUPATEN PURBALINGGA | C9: 5138 | D9: 446 | E9: 8.68 | F9: 470 | G9: 9.15 | H9: 1492 | I9: 29.04 | J9: 663 | K9: 12.9 | L9: 665 | M9: 384 | N9: 57.74 | O9: 311 | P9: 66.17 | Q9: 4796 | R9: 93.34 | S9: 82377 | T9: 44701 | U9: 43075 | V9: 96.36 | W9: 44707 | X9: 100.01 | Y9: 31950 | Z9: 18823 | AA9: 2061 | AB9: 10.95 | AC9: 18740 | AD9: 99.56 | AE9: 13008 | AF9: 3405 | AG9: 26.18 | AH9: 52649 | AI9: 12263 | AJ9: 23.29 | AK9: 65657 | AL9: 15668 | AM9: 23.86 | AN9: 29910 | AO9: 36.31 | AP9: 6732 | AQ9: 21.07 | AR9: 51638 | AS9: 206 | AT9: 79 | AU9: 65 | AV9: 104 | AW9: 59.3 | AX9: 5733 | AY9: 40 | AZ9: 5 | BA9: 32 | BB9: 346 | BC9: 840 | BD9: 12780 | BE9: 2445 | BF9: 770 | BG9: 1.72 | BH9: 29 | BI9: 0.15 | BJ9: 11237 | BK9: 3768 | BL9: 33.53
A10: 4 | B10: KABUPATEN BANJARNEGARA | C10: 3955 | D10: 400 | E10: 10.11 | F10: 319 | G10: 8.07 | H10: 949 | I10: 23.99 | J10: 624 | K10: 15.78 | L10: 500 | M10: 214 | N10: 42.8 | O10: 195 | P10: 61.13 | Q10: 3382 | R10: 85.51 | S10: 70831 | T10: 44533 | U10: 42224 | V10: 94.82 | W10: 44366 | X10: 99.62 | Y10: 30807 | Z10: 19883 | AA10: 1956 | AB10: 9.84 | AC10: 19816 | AD10: 99.66 | AE10: 30809 | AF10: 2917 | AG10: 9.47 | AH10: 115380 | AI10: 10140 | AJ10: 8.79 | AK10: 146189 | AL10: 13057 | AM10: 8.93 | AN10: 27654 | AO10: 39.04 | AP10: 17037 | AQ10: 55.3 | AR10: 48579 | AS10: 1394 | AT10: 95 | AU10: 82 | AV10: 39 | AW10: 8.13 | AX10: 18751 | AY10: 213 | AZ10: 108 | BA10: 7 | BB10: 29 | BC10: 11.21 | BD10: 13030 | BE10: 4263 | BF10: 643 | BG10: 1.44 | BH10: 5 | BI10: 0.03 | BJ10: 10530 | BK10: 5259 | BL10: 49.94
A11: 5 | B11: KABUPATEN KEBUMEN | C11: 3199 | D11: 348 | E11: 10.88 | F11: 244 | G11: 7.63 | H11: 830 | I11: 25.95 | J11: 483 | K11: 15.1 | L11: 349 | M11: 101 | N11: 28.94 | O11: 98 | P11: 40.16 | Q11: 2640 | R11: 82.53 | S11: 66775 | T11: 54809 | U11: 53823 | V11: 98.2 | W11: 54585 | X11: 99.59 | Y11: 30411 | Z11: 13312 | AA11: 317 | AB11: 2.38 | AC11: 13075 | AD11: 98.22 | AE11: 22501 | AF11: 664 | AG11: 2.95 | AH11: 85294 | AI11: 1869 | AJ11: 2.19 | AK11: 107795 | AL11: 2533 | AM11: 2.35 | AN11: 15984 | AO11: 23.94 | AP11: 8976 | AQ11: 29.52 | AR11: 24071 | AS11: 870 | AT11: 74 | AU11: 90 | AV11: 180 | AW11: 28.6 | AX11: 6495 | AY11: 296 | AZ11: 28 | BA11: 89 | BB11: 28 | BC11: 36.11 | BD11: 1698 | BE11: 690 | BF11: 811 | BG11: 1.48 | BH11: 0 | BI11: 0 | BJ11: 7564 | BK11: 4729 | BL11: 62.52
A12: 6 | B12: KABUPATEN PURWOREJO | C12: 1606 | D12: 140 | E12: 8.72 | F12: 103 | G12: 6.41 | H12: 555 | I12: 34.56 | J12: 174 | K12: 10.83 | L12: 177 | M12: 61 | N12: 34.46 | O12: 54 | P12: 52.43 | Q12: 1391 | R12: 86.61 | S12: 39377 | T12: 27824 | U12: 27352 | V12: 98.3 | W12: 27527 | X12: 98.93 | Y12: 14956 | Z12: 7539 | AA12: 373 | AB12: 4.95 | AC12: 7455 | AD12: 98.89 | AE12: 6938 | AF12: 746 | AG12: 10.75 | AH12: 27236 | AI12: 2721 | AJ12: 9.99 | AK12: 34174 | AL12: 3467 | AM12: 10.15 | AN12: 6160 | AO12: 15.64 | AP12: 2348 | AQ12: 15.7 | AR12: 11628 | AS12: 241 | AT12: 9 | AU12: 31 | AV12: 24 | AW12: 22 | AX12: 5228 | AY12: 434 | AZ12: 13 | BA12: 1 | BB12: 18 | BC12: 4.25 | BD12: 1990 | BE12: 919 | BF12: 618 | BG12: 2.22 | BH12: 1 | BI12: 0.01 | BJ12: 3588 | BK12: 1146 | BL12: 31.94
A13: 7 | B13: KABUPATEN WONOSOBO | C13: 1690 | D13: 149 | E13: 8.82 | F13: 115 | G13: 6.8 | H13: 453 | I13: 26.8 | J13: 188 | K13: 11.12 | L13: 194 | M13: 65 | N13: 33.51 | O13: 46 | P13: 40 | Q13: 1572 | R13: 93.02 | S13: 34941 | T13: 36503 | U13: 35421 | V13: 97.04 | W13: 36469 | X13: 99.91 | Y13: 18885 | Z13: 7813 | AA13: 285 | AB13: 3.65 | AC13: 7730 | AD13: 98.94 | AE13: 7653 | AF13: 142 | AG13: 1.86 | AH13: 29469 | AI13: 514 | AJ13: 1.74 | AK13: 37122 | AL13: 656 | AM13: 1.77 | AN13: 11590 | AO13: 33.17 | AP13: 3912 | AQ13: 20.71 | AR13: 13859 | AS13: 172 | AT13: 19 | AU13: 29 | AV13: 4 | AW13: 17.28 | AX13: 4313 | AY13: 265 | AZ13: 0 | BA13: 0 | BB13: 0 | BC13: 0 | BD13: 1665 | BE13: 536 | BF13: 703 | BG13: 1.93 | BH13: 6 | BI13: 0.08 | BJ13: 4242 | BK13: 417 | BL13: 9.83
A14: 8 | B14: KABUPATEN MAGELANG | C14: 1511 | D14: 180 | E14: 11.91 | F14: 108 | G14: 7.15 | H14: 480 | I14: 31.77 | J14: 224 | K14: 14.82 | L14: 154 | M14: 29 | N14: 18.83 | O14: 27 | P14: 25 | Q14: 1436 | R14: 95.04 | S14: 56988 | T14: 52299 | U14: 50091 | V14: 95.78 | W14: 52104 | X14: 99.63 | Y14: 21840 | Z14: 9766 | AA14: 293 | AB14: 3 | AC14: 9722 | AD14: 99.55 | AE14: 18806 | AF14: 683 | AG14: 3.63 | AH14: 68633 | AI14: 2307 | AJ14: 3.36 | AK14: 87439 | AL14: 2990 | AM14: 3.42 | AN14: 20218 | AO14: 35.48 | AP14: 9567 | AQ14: 43.8 | AR14: 18275 | AS14: 143 | AT14: 5 | AU14: 99 | AV14: 70 | AW14: 114.19 | AX14: 7212 | AY14: 271 | AZ14: 5 | BA14: 20 | BB14: 4 | BC14: 8.7 | BD14: 1524 | BE14: 705 | BF14: 669 | BG14: 1.28 | BH14: 0 | BI14: 0 | BJ14: 5141 | BK14: 1633 | BL14: 31.76
A15: 9 | B15: KABUPATEN BOYOLALI | C15: 2798 | D15: 379 | E15: 13.55 | F15: 136 | G15: 4.86 | H15: 601 | I15: 21.48 | J15: 222 | K15: 7.93 | L15: 351 | M15: 68 | N15: 19.37 | O15: 57 | P15: 41.91 | Q15: 2649 | R15: 94.67 | S15: 57604 | T15: 44415 | U15: 42790 | V15: 96.34 | W15: 37901 | X15: 85.33 | Y15: 24661 | Z15: 19135 | AA15: 437 | AB15: 2.28 | AC15: 13785 | AD15: 72.04 | AE15: 24663 | AF15: 804 | AG15: 3.26 | AH15: 99441 | AI15: 2713 | AJ15: 2.73 | AK15: 124104 | AL15: 3517 | AM15: 2.83 | AN15: 31407 | AO15: 54.52 | AP15: 13609 | AQ15: 55.18 | AR15: 48147 | AS15: 545 | AT15: 117 | AU15: 95 | AV15: 48 | AW15: 21.6 | AX15: 16889 | AY15: 364 | AZ15: 118 | BA15: 9 | BB15: 132 | BC15: 29.25 | BD15: 6154 | BE15: 2046 | BF15: 1507 | BG15: 3.39 | BH15: 28 | BI15: 0.15 | BJ15: 8344 | BK15: 1860 | BL15: 22.29
A16: 10 | B16: KABUPATEN KLATEN | C16: 4960 | D16: 571 | E16: 11.51 | F16: 398 | G16: 8.02 | H16: 1394 | I16: 28.1 | J16: 422 | K16: 8.51 | L16: 742 | M16: 209 | N16: 28.17 | O16: 217 | P16: 54.52 | Q16: 4747 | R16: 95.71 | S16: 86642 | T16: 47967 | U16: 47311 | V16: 98.63 | W16: 45428 | X16: 94.71 | Y16: 34786 | Z16: 21518 | AA16: 2026 | AB16: 9.42 | AC16: 17659 | AD16: 82.07 | AE16: 25216 | AF16: 2631 | AG16: 10.43 | AH16: 96831 | AI16: 7710 | AJ16: 7.96 | AK16: 122047 | AL16: 10341 | AM16: 8.47 | AN16: 32079 | AO16: 37.02 | AP16: 9773 | AQ16: 28.09 | AR16: 40336 | AS16: 1006 | AT16: 318 | AU16: 183 | AV16: 145 | AW16: 24.77 | AX16: 12618 | AY16: 170 | AZ16: 16 | BA16: 22 | BB16: 70 | BC16: 49.46 | BD16: 6494 | BE16: 2407 | BF16: 718 | BG16: 1.5 | BH16: 39 | BI16: 0.18 | BJ16: 10844 | BK16: 5194 | BL16: 47.9
A17: 11 | B17: KABUPATEN SUKOHARJO | C17: 4418 | D17: 357 | E17: 8.08 | F17: 267 | G17: 6.04 | H17: 984 | I17: 22.27 | J17: 303 | K17: 6.86 | L17: 418 | M17: 164 | N17: 39.23 | O17: 151 | P17: 56.55 | Q17: 4266 | R17: 96.56 | S17: 65656 | T17: 35806 | U17: 35754 | V17: 99.85 | W17: 35803 | X17: 99.99 | Y17: 25186 | Z17: 17577 | AA17: 5194 | AB17: 29.55 | AC17: 17083 | AD17: 97.19 | AE17: 20546 | AF17: 3530 | AG17: 17.18 | AH17: 75883 | AI17: 12941 | AJ17: 17.05 | AK17: 96429 | AL17: 16471 | AM17: 17.08 | AN17: 36809 | AO17: 56.06 | AP17: 4288 | AQ17: 17.03 | AR17: 65295 | AS17: 274 | AT17: 58 | AU17: 25 | AV17: 70 | AW17: 28.61 | AX17: 5773 | AY17: 76 | AZ17: 0 | BA17: 0 | BB17: 0 | BC17: 0 | BD17: 14809 | BE17: 4368 | BF17: 2662 | BG17: 7.43 | BH17: 600 | BI17: 3.41 | BJ17: 8778 | BK17: 4114 | BL17: 46.87
A18: 12 | B18: KABUPATEN WONOGIRI | C18: 1848 | D18: 275 | E18: 14.88 | F18: 146 | G18: 7.9 | H18: 549 | I18: 29.71 | J18: 228 | K18: 12.34 | L18: 310 | M18: 89 | N18: 28.71 | O18: 87 | P18: 59.59 | Q18: 1685 | R18: 91.18 | S18: 34234 | T18: 31633 | U18: 31497 | V18: 99.57 | W18: 31356 | X18: 99.12 | Y18: 14447 | Z18: 11440 | AA18: 1346 | AB18: 11.77 | AC18: 11259 | AD18: 98.42 | AE18: 12590 | AF18: 1164 | AG18: 9.25 | AH18: 46915 | AI18: 4004 | AJ18: 8.53 | AK18: 59505 | AL18: 5168 | AM18: 8.68 | AN18: 62500 | AO18: 182.57 | AP18: 22838 | AQ18: 158.08 | AR18: 84526 | AS18: 1262 | AT18: 220 | AU18: 98 | AV18: 265 | AW18: 24.49 | AX18: 24707 | AY18: 414 | AZ18: 54 | BA18: 80 | BB18: 99 | BC18: 38.25 | BD18: 8787 | BE18: 3080 | BF18: 1468 | BG18: 4.64 | BH18: 59 | BI18: 0.52 | BJ18: 5872 | BK18: 2656 | BL18: 45.23
A19: 13 | B19: KABUPATEN KARANGANYAR | C19: 786 | D19: 54 | E19: 6.87 | F19: 51 | G19: 6.49 | H19: 184 | I19: 23.41 | J19: 57 | K19: 7.25 | L19: 64 | M19: 16 | N19: 25 | O19: 15 | P19: 29.41 | Q19: 693 | R19: 88.17 | S19: 18947 | T19: 39451 | U19: 37802 | V19: 95.82 | W19: 39322 | X19: 99.67 | Y19: 7271 | Z19: 3569 | AA19: 77 | AB19: 2.16 | AC19: 3504 | AD19: 98.18 | AE19: 5763 | AF19: 102 | AG19: 1.77 | AH19: 20296 | AI19: 306 | AJ19: 1.51 | AK19: 26059 | AL19: 408 | AM19: 1.57 | AN19: 5481 | AO19: 28.93 | AP19: 2511 | AQ19: 34.53 | AR19: 5491 | AS19: 17 | AT19: 3 | AU19: 2 | AV19: 4 | AW19: 30 | AX19: 2286 | AY19: 49 | AZ19: 4 | BA19: 0 | BB19: 0 | BC19: 0 | BD19: 783 | BE19: 390 | BF19: 206 | BG19: 0.52 | BH19: 2 | BI19: 0.06 | BJ19: 1809 | BK19: 237 | BL19: 13.1
A20: 14 | B20: KABUPATEN SRAGEN | C20: 1132 | D20: 104 | E20: 9.19 | F20: 57 | G20: 5.04 | H20: 206 | I20: 18.2 | J20: 84 | K20: 7.42 | L20: 119 | M20: 29 | N20: 24.37 | O20: 28 | P20: 49.12 | Q20: 1057 | R20: 93.37 | S20: 34598 | T20: 37302 | U20: 34854 | V20: 93.44 | W20: 37074 | X20: 99.39 | Y20: 10920 | Z20: 4586 | AA20: 50 | AB20: 1.09 | AC20: 4578 | AD20: 99.83 | AE20: 6606 | AF20: 112 | AG20: 1.7 | AH20: 24436 | AI20: 405 | AJ20: 1.66 | AK20: 31042 | AL20: 517 | AM20: 1.67 | AN20: 2846 | AO20: 8.23 | AP20: 961 | AQ20: 8.8 | AR20: 2567 | AS20: 32 | AT20: 0 | AU20: 0 | AV20: 7 | AW20: 21.88 | AX20: 665 | AY20: 7 | AZ20: 0 | BA20: 2 | BB20: 0 | BC20: 28.57 | BD20: 1194 | BE20: 122 | BF20: 565 | BG20: 1.51 | BH20: 0 | BI20: 0 | BJ20: 2813 | BK20: 338 | BL20: 12.02
A21: 15 | B21: KABUPATEN GROBOGAN | C21: 808 | D21: 100 | E21: 12.38 | F21: 47 | G21: 5.82 | H21: 136 | I21: 16.83 | J21: 135 | K21: 16.71 | L21: 119 | M21: 17 | N21: 14.29 | O21: 12 | P21: 25.53 | Q21: 772 | R21: 95.54 | S21: 35529 | T21: 59787 | U21: 56023 | V21: 93.7 | W21: 58345 | X21: 97.59 | Y21: 17147 | Z21: 7164 | AA21: 819 | AB21: 11.43 | AC21: 6961 | AD21: 97.17 | AE21: 9703 | AF21: 1977 | AG21: 20.38 | AH21: 35357 | AI21: 4753 | AJ21: 13.44 | AK21: 45060 | AL21: 6730 | AM21: 14.94 | AN21: 12841 | AO21: 36.14 | AP21: 11239 | AQ21: 65.54 | AR21: 30045 | AS21: 4032 | AT21: 53 | AU21: 2 | AV21: 302 | AW21: 7.44 | AX21: 14152 | AY21: 77 | AZ21: 4 | BA21: 2 | BB21: 4 | BC21: 7.41 | BD21: 6228 | BE21: 2032 | BF21: 1079 | BG21: 1.8 | BH21: 147 | BI21: 2.05 | BJ21: 3219 | BK21: 1845 | BL21: 57.32
A22: 16 | B22: KABUPATEN BLORA | C22: 4130 | D22: 311 | E22: 7.53 | F22: 275 | G22: 6.66 | H22: 667 | I22: 16.15 | J22: 318 | K22: 7.7 | L22: 403 | M22: 262 | N22: 65.01 | O22: 221 | P22: 80.36 | Q22: 3917 | R22: 94.84 | S22: 64675 | T22: 34618 | U22: 34270 | V22: 98.99 | W22: 34000 | X22: 98.21 | Y22: 22298 | Z22: 16648 | AA22: 5889 | AB22: 35.37 | AC22: 16437 | AD22: 98.73 | AE22: 15481 | AF22: 5247 | AG22: 33.89 | AH22: 57682 | AI22: 19667 | AJ22: 34.1 | AK22: 73163 | AL22: 24914 | AM22: 34.05 | AN22: 23888 | AO22: 36.94 | AP22: 12197 | AQ22: 54.7 | AR22: 84129 | AS22: 419 | AT22: 52 | AU22: 32 | AV22: 152 | AW22: 39.07 | AX22: 29187 | AY22: 208 | AZ22: 15 | BA22: 12 | BB22: 15 | BC22: 12.11 | BD22: 15044 | BE22: 6970 | BF22: 999 | BG22: 2.89 | BH22: 55 | BI22: 0.33 | BJ22: 8407 | BK22: 7012 | BL22: 83.41
A23: 17 | B23: KABUPATEN REMBANG | C23: 3529 | D23: 259 | E23: 7.34 | F23: 208 | G23: 5.89 | H23: 409 | I23: 11.59 | J23: 285 | K23: 8.08 | L23: 300 | M23: 178 | N23: 59.33 | O23: 155 | P23: 74.52 | Q23: 3018 | R23: 85.52 | S23: 48665 | T23: 29429 | U23: 26579 | V23: 90.32 | W23: 28876 | X23: 98.12 | Y23: 19405 | Z23: 13449 | AA23: 3417 | AB23: 25.41 | AC23: 13374 | AD23: 99.44 | AE23: 6596 | AF23: 1067 | AG23: 16.18 | AH23: 26956 | AI23: 4210 | AJ23: 15.62 | AK23: 33552 | AL23: 5277 | AM23: 15.73 | AN23: 25649 | AO23: 52.71 | AP23: 9733 | AQ23: 50.16 | AR23: 39777 | AS23: 403 | AT23: 22 | AU23: 23 | AV23: 43 | AW23: 15.53 | AX23: 13368 | AY23: 221 | AZ23: 9 | BA23: 1 | BB23: 11 | BC23: 5.22 | BD23: 11049 | BE23: 4245 | BF23: 840 | BG23: 2.85 | BH23: 24 | BI23: 0.18 | BJ23: 6951 | BK23: 1525 | BL23: 21.94
A24: 18 | B24: KABUPATEN PATI | C24: 3195 | D24: 232 | E24: 7.26 | F24: 170 | G24: 5.32 | H24: 476 | I24: 14.9 | J24: 169 | K24: 5.29 | L24: 311 | M24: 78 | N24: 25.08 | O24: 82 | P24: 48.24 | Q24: 3018 | R24: 94.46 | S24: 38299 | T24: 54248 | U24: 50435 | V24: 92.97 | W24: 53955 | X24: 99.46 | Y24: 20638 | Z24: 13397 | AA24: 952 | AB24: 7.11 | AC24: 13313 | AD24: 99.37 | AE24: 14734 | AF24: 1287 | AG24: 8.73 | AH24: 55180 | AI24: 4056 | AJ24: 7.35 | AK24: 69914 | AL24: 5343 | AM24: 7.64 | AN24: 14704 | AO24: 38.39 | AP24: 15018 | AQ24: 72.77 | AR24: 44011 | AS24: 477 | AT24: 50 | AU24: 80 | AV24: 23 | AW24: 19.54 | AX24: 21541 | AY24: 942 | AZ24: 12 | BA24: 10 | BB24: 46 | BC24: 5.87 | BD24: 5891 | BE24: 2949 | BF24: 931 | BG24: 1.72 | BH24: 123 | BI24: 0.92 | BJ24: 6552 | BK24: 1804 | BL24: 27.53
A25: 19 | B25: KABUPATEN KUDUS | C25: 4559 | D25: 236 | E25: 5.18 | F25: 187 | G25: 4.1 | H25: 642 | I25: 14.08 | J25: 138 | K25: 3.03 | L25: 344 | M25: 110 | N25: 31.98 | O25: 84 | P25: 44.92 | Q25: 4153 | R25: 91.09 | S25: 65479 | T25: 40677 | U25: 39944 | V25: 98.2 | W25: 40544 | X25: 99.67 | Y25: 26403 | Z25: 13733 | AA25: 1366 | AB25: 9.95 | AC25: 13790 | AD25: 100.42 | AE25: 9055 | AF25: 245 | AG25: 2.71 | AH25: 31836 | AI25: 580 | AJ25: 1.82 | AK25: 40891 | AL25: 825 | AM25: 2.02 | AN25: 48860 | AO25: 74.62 | AP25: 17815 | AQ25: 67.47 | AR25: 48619 | AS25: 581 | AT25: 259 | AU25: 293 | AV25: 203 | AW25: 59.05 | AX25: 15693 | AY25: 390 | AZ25: 18 | BA25: 105 | BB25: 9 | BC25: 27.94 | BD25: 8550 | BE25: 2878 | BF25: 1566 | BG25: 3.85 | BH25: 44 | BI25: 0.32 | BJ25: 11060 | BK25: 4969 | BL25: 44.93
A26: 20 | B26: KABUPATEN JEPARA | C26: 3916 | D26: 365 | E26: 9.32 | F26: 196 | G26: 5.01 | H26: 595 | I26: 15.19 | J26: 378 | K26: 9.65 | L26: 466 | M26: 77 | N26: 16.52 | O26: 77 | P26: 39.29 | Q26: 3751 | R26: 95.79 | S26: 90322 | T26: 56278 | U26: 54437 | V26: 96.73 | W26: 56167 | X26: 99.8 | Y26: 35980 | Z26: 20884 | AA26: 443 | AB26: 2.12 | AC26: 20740 | AD26: 99.31 | AE26: 19704 | AF26: 299 | AG26: 1.52 | AH26: 80818 | AI26: 896 | AJ26: 1.11 | AK26: 100522 | AL26: 1195 | AM26: 1.19 | AN26: 44052 | AO26: 48.77 | AP26: 16245 | AQ26: 45.15 | AR26: 53728 | AS26: 904 | AT26: 150 | AU26: 143 | AV26: 48 | AW26: 18.12 | AX26: 26119 | AY26: 797 | AZ26: 1839 | BA26: 36 | BB26: 2 | BC26: 1.44 | BD26: 6881 | BE26: 2639 | BF26: 2402 | BG26: 4.27 | BH26: 89 | BI26: 0.43 | BJ26: 10526 | BK26: 3582 | BL26: 34.03
A27: 21 | B27: KABUPATEN DEMAK | C27: 4429 | D27: 377 | E27: 8.51 | F27: 176 | G27: 3.97 | H27: 444 | I27: 10.02 | J27: 235 | K27: 5.31 | L27: 431 | M27: 87 | N27: 20.19 | O27: 83 | P27: 47.16 | Q27: 4126 | R27: 93.16 | S27: 85912 | T27: 64195 | U27: 63952 | V27: 99.62 | W27: 62931 | X27: 98.03 | Y27: 35486 | Z27: 19797 | AA27: 3577 | AB27: 18.07 | AC27: 19300 | AD27: 97.49 | AE27: 22060 | AF27: 3961 | AG27: 17.96 | AH27: 90562 | AI27: 12073 | AJ27: 13.33 | AK27: 112622 | AL27: 16034 | AM27: 14.24 | AN27: 57761 | AO27: 67.23 | AP27: 21735 | AQ27: 61.25 | AR27: 63211 | AS27: 547 | AT27: 284 | AU27: 102 | AV27: 226 | AW27: 39.47 | AX27: 21583 | AY27: 301 | AZ27: 104 | BA27: 25 | BB27: 437 | BC27: 114.07 | BD27: 7635 | BE27: 3036 | BF27: 2324 | BG27: 3.62 | BH27: 339 | BI27: 1.71 | BJ27: 11304 | BK27: 7165 | BL27: 63.38
A28: 22 | B28: KABUPATEN SEMARANG | C28: 2064 | D28: 247 | E28: 11.97 | F28: 108 | G28: 5.23 | H28: 276 | I28: 13.37 | J28: 191 | K28: 9.25 | L28: 240 | M28: 55 | N28: 22.92 | O28: 44 | P28: 40.74 | Q28: 1947 | R28: 94.33 | S28: 49344 | T28: 50372 | U28: 49291 | V28: 97.85 | W28: 50211 | X28: 99.68 | Y28: 19525 | Z28: 11714 | AA28: 271 | AB28: 2.31 | AC28: 11713 | AD28: 99.99 | AE28: 12315 | AF28: 914 | AG28: 7.42 | AH28: 46561 | AI28: 3178 | AJ28: 6.83 | AK28: 58876 | AL28: 4092 | AM28: 6.95 | AN28: 23321 | AO28: 47.26 | AP28: 7514 | AQ28: 38.48 | AR28: 23172 | AS28: 112 | AT28: 44 | AU28: 28 | AV28: 44 | AW28: 46.15 | AX28: 5673 | AY28: 26 | AZ28: 7 | BA28: 2 | BB28: 744 | BC28: 2260.61 | BD28: 5949 | BE28: 2961 | BF28: 890 | BG28: 1.77 | BH28: 15 | BI28: 0.13 | BJ28: 6345 | BK28: 3198 | BL28: 50.4
A29: 23 | B29: KABUPATEN TEMANGGUNG | C29: 2144 | D29: 168 | E29: 7.84 | F29: 148 | G29: 6.9 | H29: 384 | I29: 17.91 | J29: 234 | K29: 10.91 | L29: 213 | M29: 72 | N29: 33.8 | O29: 63 | P29: 42.57 | Q29: 1949 | R29: 90.9 | S29: 53950 | T29: 26906 | U29: 26491 | V29: 98.46 | W29: 26087 | X29: 96.96 | Y29: 21776 | Z29: 12331 | AA29: 2978 | AB29: 24.15 | AC29: 12246 | AD29: 99.31 | AE29: 15265 | AF29: 554 | AG29: 3.63 | AH29: 58859 | AI29: 1716 | AJ29: 2.92 | AK29: 74124 | AL29: 2270 | AM29: 3.06 | AN29: 17126 | AO29: 31.74 | AP29: 7720 | AQ29: 35.45 | AR29: 21207 | AS29: 367 | AT29: 120 | AU29: 21 | AV29: 58 | AW29: 16.22 | AX29: 8266 | AY29: 251 | AZ29: 166 | BA29: 12 | BB29: 218 | BC29: 55.16 | BD29: 6589 | BE29: 1926 | BF29: 962 | BG29: 3.58 | BH29: 9 | BI29: 0.07 | BJ29: 6486 | BK29: 3006 | BL29: 46.35
A30: 24 | B30: KABUPATEN KENDAL | C30: 5472 | D30: 578 | E30: 10.56 | F30: 355 | G30: 6.49 | H30: 982 | I30: 17.95 | J30: 562 | K30: 10.27 | L30: 693 | M30: 168 | N30: 24.24 | O30: 159 | P30: 44.79 | Q30: 4958 | R30: 90.61 | S30: 79007 | T30: 45514 | U30: 44509 | V30: 97.79 | W30: 45304 | X30: 99.54 | Y30: 29077 | Z30: 16739 | AA30: 693 | AB30: 4.14 | AC30: 16773 | AD30: 100.2 | AE30: 20821 | AF30: 1981 | AG30: 9.51 | AH30: 80907 | AI30: 7389 | AJ30: 9.13 | AK30: 101728 | AL30: 9370 | AM30: 9.21 | AN30: 24284 | AO30: 30.74 | AP30: 9969 | AQ30: 34.28 | AR30: 41099 | AS30: 787 | AT30: 46 | AU30: 32 | AV30: 41 | AW30: 8.76 | AX30: 10796 | AY30: 650 | AZ30: 27 | BA30: 177 | BB30: 2 | BC30: 26.44 | BD30: 8760 | BE30: 1629 | BF30: 1647 | BG30: 3.62 | BH30: 100 | BI30: 0.6 | BJ30: 10690 | BK30: 3426 | BL30: 32.05
A31: 25 | B31: KABUPATEN BATANG | C31: 5140 | D31: 319 | E31: 6.21 | F31: 341 | G31: 6.63 | H31: 715 | I31: 13.91 | J31: 499 | K31: 9.71 | L31: 453 | M31: 338 | N31: 74.61 | O31: 313 | P31: 91.79 | Q31: 4912 | R31: 95.56 | S31: 65430 | T31: 38095 | U31: 36347 | V31: 95.41 | W31: 38006 | X31: 99.77 | Y31: 25843 | Z31: 14849 | AA31: 802 | AB31: 5.4 | AC31: 13534 | AD31: 91.14 | AE31: 6926 | AF31: 6385 | AG31: 92.19 | AH31: 28621 | AI31: 24979 | AJ31: 87.28 | AK31: 35547 | AL31: 31364 | AM31: 88.23 | AN31: 20463 | AO31: 31.27 | AP31: 11395 | AQ31: 44.09 | AR31: 60837 | AS31: 935 | AT31: 25 | AU31: 16 | AV31: 6 | AW31: 2.29 | AX31: 9207 | AY31: 76 | AZ31: 15 | BA31: 3 | BB31: 0 | BC31: 3.3 | BD31: 8550 | BE31: 2243 | BF31: 1118 | BG31: 2.93 | BH31: 46 | BI31: 0.31 | BJ31: 10582 | BK31: 3887 | BL31: 36.73
A32: 26 | B32: KABUPATEN PEKALONGAN | C32: 3664 | D32: 295 | E32: 8.05 | F32: 206 | G32: 5.62 | H32: 613 | I32: 16.73 | J32: 386 | K32: 10.53 | L32: 351 | M32: 135 | N32: 38.46 | O32: 132 | P32: 64.08 | Q32: 3406 | R32: 92.96 | S32: 68497 | T32: 44972 | U32: 42713 | V32: 94.98 | W32: 44839 | X32: 99.7 | Y32: 31562 | Z32: 12273 | AA32: 1579 | AB32: 12.87 | AC32: 12121 | AD32: 98.76 | AE32: 19308 | AF32: 824 | AG32: 4.27 | AH32: 72271 | AI32: 2737 | AJ32: 3.79 | AK32: 91579 | AL32: 3561 | AM32: 3.89 | AN32: 47847 | AO32: 69.85 | AP32: 9883 | AQ32: 31.31 | AR32: 29848 | AS32: 119 | AT32: 192 | AU32: 15 | AV32: 66 | AW32: 26.05 | AX32: 10470 | AY32: 317 | AZ32: 21 | BA32: 26 | BB32: 42 | BC32: 20.12 | BD32: 5654 | BE32: 2465 | BF32: 772 | BG32: 1.72 | BH32: 20 | BI32: 0.16 | BJ32: 9014 | BK32: 5029 | BL32: 55.79
... A35: 29 | B35: KABUPATEN BREBES | C35: 3972 | D35: 638 | E35: 16.06 | F35: 220 | G35: 5.54 | H35: 786 | I35: 19.79 | J35: 479 | K35: 12.06 | L35: 699 | M35: 92 | N35: 13.16 | O35: 91 | P35: 41.36 | Q35: 3663 | R35: 92.22 | S35: 89407 | T35: 82605 | U35: 73892 | V35: 89.45 | W35: 82494 | X35: 99.87 | Y35: 28084 | Z35: 13125 | AA35: 762 | AB35: 5.81 | AC35: 13114 | AD35: 99.92 | AE35: 13803 | AF35: 317 | AG35: 2.3 | AH35: 51596 | AI35: 691 | AJ35: 1.34 | AK35: 65399 | AL35: 1008 | AM35: 1.54 | AN35: 20502 | AO35: 22.93 | AP35: 3161 | AQ35: 11.26 | AR35: 29600 | AS35: 1489 | AT35: 38 | AU35: 63 | AV35: 62 | AW35: 8.19 | AX35: 3571 | AY35: 165 | AZ35: 28 | BA35: 12 | BB35: 54 | BC35: 34.2 | BD35: 3716 | BE35: 1975 | BF35: 1614 | BG35: 1.95 | BH35: 4 | BI35: 0.03 | BJ35: 9235 | BK35: 1517 | BL35: 16.43
A36: 30 | B36: KOTA MAGELANG | C36: 369 | D36: 20 | E36: 5.42 | F36: 23 | G36: 6.23 | H36: 165 | I36: 44.72 | J36: 35 | K36: 9.49 | L36: 34 | M36: 15 | N36: 44.12 | O36: 17 | P36: 73.91 | Q36: 301 | R36: 81.57 | S36: 6976 | T36: 3295 | U36: 3193 | V36: 96.9 | W36: 3294 | X36: 99.97 | Y36: 2839 | Z36: 1671 | AA36: 12 | AB36: 0.72 | AC36: 1671 | AD36: 100 | AE36: 1597 | AF36: 180 | AG36: 11.27 | AH36: 6222 | AI36: 510 | AJ36: 8.2 | AK36: 7819 | AL36: 690 | AM36: 8.82 | AN36: 2396 | AO36: 34.35 | AP36: 1665 | AQ36: 58.65 | AR36: 2290 | AS36: 62 | AT36: 58 | AU36: 57 | AV36: 44 | AW36: 84.17 | AX36: 1628 | AY36: 38 | AZ36: 20 | BA36: 33 | BB36: 20 | BC36: 91.38 | BD36: 486 | BE36: 127 | BF36: 59 | BG36: 1.79 | BH36: 0 | BI36: 0 | BJ36: 772 | BK36: 195 | BL36: 25.26
A37: 31 | B37: KOTA SURAKARTA | C37: 1178 | D37: 62 | E37: 5.26 | F37: 68 | G37: 5.77 | H37: 275 | I37: 23.34 | J37: 44 | K37: 3.74 | L37: 84 | M37: 37 | N37: 44.05 | O37: 29 | P37: 42.65 | Q37: 1145 | R37: 97.2 | S37: 35043 | T37: 16480 | U37: 16329 | V37: 99.08 | W37: 16464 | X37: 99.9 | Y37: 13391 | Z37: 7172 | AA37: 950 | AB37: 13.25 | AC37: 7123 | AD37: 99.32 | AE37: 9429 | AF37: 1639 | AG37: 17.38 | AH37: 36669 | AI37: 6041 | AJ37: 16.47 | AK37: 46098 | AL37: 7680 | AM37: 16.66 | AN37: 10536 | AO37: 30.07 | AP37: 6677 | AQ37: 49.86 | AR37: 10903 | AS37: 221 | AT37: 152 | AU37: 47 | AV37: 151 | AW37: 53.08 | AX37: 7427 | AY37: 27 | AZ37: 50 | BA37: 26 | BB37: 46 | BC37: 93.51 | BD37: 2486 | BE37: 975 | BF37: 101 | BG37: 0.61 | BH37: 0 | BI37: 0 | BJ37: 3190 | BK37: 1256 | BL37: 39.37
A38: 32 | B38: KOTA SALATIGA | C38: 787 | D38: 30 | E38: 3.81 | F38: 56 | G38: 7.12 | H38: 150 | I38: 19.06 | J38: 45 | K38: 5.72 | L38: 63 | M38: 51 | N38: 80.95 | O38: 48 | P38: 85.71 | Q38: 731 | R38: 92.88 | S38: 15553 | T38: 5837 | U38: 5549 | V38: 95.07 | W38: 5831 | X38: 99.9 | Y38: 5593 | Z38: 3144 | AA38: 888 | AB38: 28.24 | AC38: 3144 | AD38: 100 | AE38: 4351 | AF38: 1394 | AG38: 32.04 | AH38: 17701 | AI38: 4619 | AJ38: 26.09 | AK38: 22052 | AL38: 6013 | AM38: 27.27 | AN38: 8783 | AO38: 56.47 | AP38: 9329 | AQ38: 166.8 | AR38: 9464 | AS38: 86 | AT38: 12 | AU38: 26 | AV38: 12 | AW38: 38.78 | AX38: 8175 | AY38: 274 | AZ38: 40 | BA38: 36 | BB38: 36 | BC38: 22.93 | BD38: 1311 | BE38: 1146 | BF38: 51 | BG38: 0.87 | BH38: 0 | BI38: 0 | BJ38: 1546 | BK38: 831 | BL38: 53.75
A39: 33 | B39: KOTA SEMARANG | C39: 6029 | D39: 151 | E39: 2.5 | F39: 123 | G39: 2.04 | H39: 871 | I39: 14.45 | J39: 145 | K39: 2.41 | L39: 196 | M39: 82 | N39: 41.84 | O39: 49 | P39: 39.84 | Q39: 6033 | R39: 100.07 | S39: 103540 | T39: 62024 | U39: 55435 | V39: 89.38 | W39: 61972 | X39: 99.92 | Y39: 43140 | Z39: 20502 | AA39: 1360 | AB39: 6.63 | AC39: 20392 | AD39: 99.46 | AE39: 32050 | AF39: 3338 | AG39: 10.41 | AH39: 117208 | AI39: 12150 | AJ39: 10.37 | AK39: 149258 | AL39: 15488 | AM39: 10.38 | AN39: 31652 | AO39: 30.57 | AP39: 18301 | AQ39: 42.42 | AR39: 39167 | AS39: 1040 | AT39: 108 | AU39: 76 | AV39: 44 | AW39: 10.45 | AX39: 19519 | AY39: 762 | AZ39: 32 | BA39: 54 | BB39: 445 | BC39: 62.85 | BD39: 4092 | BE39: 2045 | BF39: 856 | BG39: 1.38 | BH39: 125 | BI39: 0.61 | BJ39: 12136 | BK39: 5173 | BL39: 42.63
A40: 34 | B40: KOTA PEKALONGAN | C40: 1962 | D40: 116 | E40: 5.91 | F40: 158 | G40: 8.05 | H40: 499 | I40: 25.43 | J40: 125 | K40: 6.37 | L40: 211 | M40: 133 | N40: 63.03 | O40: 153 | P40: 96.84 | Q40: 1931 | R40: 98.42 | S40: 26603 | T40: 13752 | U40: 13111 | V40: 95.34 | W40: 13552 | X40: 98.55 | Y40: 9821 | Z40: 6310 | AA40: 6172 | AB40: 97.81 | AC40: 6294 | AD40: 99.75 | AE40: 2467 | AF40: 1774 | AG40: 71.91 | AH40: 11067 | AI40: 8221 | AJ40: 74.28 | AK40: 13534 | AL40: 9995 | AM40: 73.85 | AN40: 9744 | AO40: 36.63 | AP40: 5888 | AQ40: 59.95 | AR40: 9387 | AS40: 208 | AT40: 145 | AU40: 143 | AV40: 146 | AW40: 81.87 | AX40: 5948 | AY40: 112 | AZ40: 103 | BA40: 84 | BB40: 103 | BC40: 86.98 | BD40: 1671 | BE40: 3178 | BF40: 732 | BG40: 5.32 | BH40: 534 | BI40: 8.46 | BJ40: 3763 | BK40: 3750 | BL40: 99.65
A41: 35 | B41: KOTA TEGAL | C41: 260 | D41: 8 | E41: 3.08 | F41: 16 | G41: 6.15 | H41: 60 | I41: 23.08 | J41: 10 | K41: 3.85 | L41: 15 | M41: 9 | N41: 60 | O41: 6 | P41: 37.5 | Q41: 249 | R41: 95.77 | S41: 10682 | T41: 7789 | U41: 7654 | V41: 98.27 | W41: 7780 | X41: 99.88 | Y41: 4472 | Z41: 948 | AA41: 34 | AB41: 3.59 | AC41: 919 | AD41: 96.94 | AE41: 1378 | AF41: 70 | AG41: 5.08 | AH41: 4499 | AI41: 207 | AJ41: 4.6 | AK41: 5877 | AL41: 277 | AM41: 4.71 | AN41: 4731 | AO41: 44.29 | AP41: 4936 | AQ41: 110.38 | AR41: 4576 | AS41: 0 | AT41: 0 | AU41: 0 | AV41: 0 | AW41: 0 | AX41: 4885 | AY41: 33 | AZ41: 0 | BA41: 16 | BB41: 0 | BC41: 48.48 | BD41: 761 | BE41: 622 | BF41: 52 | BG41: 0.67 | BH41: 7 | BI41: 0.74 | BJ41: 684 | BK41: 240 | BL41: 35.09
A42: JUMLAH | C42: 118250 | D42: 10760 | E42: 9.1 | F42: 7374 | G42: 6.24 | H42: 23713 | I42: 20.05 | J42: 11503 | K42: 9.73 | L42: 13153 | M42: 4557 | N42: 34.65 | O42: 4166 | P42: 56.5 | Q42: 110355 | R42: 93.32 | S42: 2198023 | T42: 1520999 | U42: 1462399 | V42: 96.15 | W42: 1501716 | X42: 98.73 | Y42: 879374 | Z42: 490135 | AA42: 53873 | AB42: 10.99 | AC42: 474755 | AD42: 96.86 | AE42: 552107 | AF42: 67914 | AG42: 12.3 | AH42: 2111798 | AI42: 244609 | AJ42: 11.58 | AK42: 2663905 | AL42: 312523 | AM42: 11.73 | AN42: 908129 | AO42: 41.32 | AP42: 378701 | AQ42: 43.06 | AR42: 1275554 | AS42: 22548 | AT42: 3631 | AU42: 2756 | AV42: 2954 | AW42: 21.81 | AX42: 427012 | AY42: 10421 | AZ42: 3139 | BA42: 1073 | BB42: 3239 | BC42: 31.8 | BD42: 228846 | BE42: 85109 | BF42: 39567 | BG42: 2.6 | BH42: 2772 | BI42: 0.57 | BJ42: 275635 | BK42: 113712 | BL42: 41.25

Sheet gizi
A1: Data Tarik : 2026-10-01 04:21:13
A2: Penarikan Data (Update) dilakukan secara rutin 8 jam sekali
A3: No | B3: Kabupaten/Kota | C3: Pemantauan Pertumbuhan dan Perkembangan | AF3: Masalah gizi | AN3: ASI Eksklusif dan MPASI | BF3: Cakupan pemberian suplementasi vitamin A pada balita usia 6-59 bulan | CC3: Tatalaksana Balita Bermasalah Gizi
C4: Jumlah sasaran balita | D4: Jumlah balita usia 0-23 bulan ini (avg) | E4: Jumlah balita usia 24-59 bulan ini (avg) | F4: Jumlah balita usia 0-59 bulan ini (avg) | G4: Jumlah balita usia 0-23 ditimbang bulan ini (avg) | H4: % | I4: Jumlah balita usia 24-59 ditimbang bulan ini (avg) | J4: % | K4: Jumlah balita usia 0-59 ditimbang bulan ini (avg) | L4: % | M4: Jumlah balita usia 0-23 diukur PB/TB bulan ini (avg) | N4: % | O4: Jumlah balita usia 24-59 diukur PB/TB bulan ini (avg) | P4: % | Q4: Jumlah balita usia 0-59 diukur PB/TB bulan ini (avg) | R4: % | S4: Jumlah balita usia 0-23 ditimbang dan diukur bulan ini (avg) | T4: % | U4: Jumlah balita usia 24-59 ditimbang dan diukur bulan ini (avg) | V4: % | W4: Jumlah balita usia 0-59 ditimbang dan diukur bulan ini (avg) | X4: % | Y4: Pemantauan Pertumbuhan | AH4: Persentase balita stunting (pendek dan sangat pendek) pada balita | AJ4: Persentase balita wasting (gizi kurang dan gizi buruk) pada balita | AL4: Persentase balita overweight (gizi lebih dan obesitas) pada balita | AN4: Persentase balita underweight (berat badan kurang dan sangat kurang) pada balita | AP4: Persentase bayi usia <6 bulan mendapat ASI Eksklusif | AT4: Persentase bayi usia 6 bulan mendapat ASI Eksklusif | AW4: Persentase Anak 6-23 bulan mendapat MPASI | BF4: Data bulanan | BT4: Tahunan | CC4: Persentase balita gizi kurang mendapat makanan tambahan | CF4: Persentase balita berat badan kurang mendapat makanan tambahan | CI4: Persentase balita berat badan tidak naik (T) mendapat makanan tambahan | CL4: % Rerata balita bermasalah gizi mendapat makanan tambahan | CM4: Persentase balita gizi buruk mendapat tata laksana | CY4: Persentase balita stunting dirujuk PKM ke RS
